Workbook

Sheet Summary
A1: Jijo P Isaac — Mutual Fund Portfolio Report
A2: Statement period: 01-Aug-2023 to 01-Aug-2026 | PAN: AKZPJ9044N | Source: CAS detailed report (cas_detailed_report_2026_08_01_124122.xlsx) | Rebuilt: 01-Aug-2026
A4: KEY METRICS
A5: Total Invested (Rs.) — active holdings | D5: ='Holdings & Returns'!F13 -> 9954143.4
A6: Current Portfolio Value (Rs.) | D6: ='Holdings & Returns'!G13 -> 11826023
A7: Absolute Gain / Loss (Rs.) | D7: =D6-D5 -> 1871879.4
A8: Absolute Return (%) - since inception, blended | D8: =D7/D5 -> 0.18805028
A9: Portfolio XIRR - cash-flow-verified funds (~90% of capital)* | D9: =XIRR(Transactions!B108:B190,Transactions!A108:A190) -> 0.14166383
A10: Number of active fund holdings | D10: =COUNTA('Holdings & Returns'!A5:A12) -> 8
A11: Number of AMCs (active holdings) | D11: 7
A12: Realized gain/loss on exited folios (Rs.) | D12: ='Exited Positions'!G8 -> -9492.61
A13: *XIRR excludes Axis Mid Cap Fund (Rs.9,45,542 invested) - its transaction history is absent from the source CAS. See Data Quality Notes tab.
A15: WHAT'S IN THIS WORKBOOK
A16: - Holdings & Returns -- every active fund with XIRR, 3M/6M/1Y/3Y/5Y returns, weight, and gain/loss (Section 1).
A17: - Classification & Analysis -- asset-class / market-cap / AMC breakdown, portfolio health assessment and action items (Section 2).
A18: - Transactions -- full cleaned transaction log per fund, used to drive the XIRR formulas.
A19: - NAV History (Source Data) -- NAV reference points behind the trailing return calculations, with source.
A20: - Exited Positions -- three fully redeemed folios with realized gain/loss.
A21: - Data Quality Notes -- gaps and quirks found in the source CAS, and what to do about them.

Sheet Holdings & Returns
A1: Section 1 — Portfolio Holdings & Returns (active funds)
A2: Holdings and returns consolidated from the CAS. XIRR = money-weighted return from actual cash flows (see Transactions tab). 3M/6M = absolute return; 1Y/3Y/5Y = annualised (CAGR), point-to-point on fund NAV.
A4: Scheme | B4: AMC | C4: Asset Class | D4: Segment | E4: Folio No. | F4: Invested (₹) | G4: Current Value (₹) | H4: Gain/Loss (₹) | I4: Total Return % | J4: Weight % | K4: XIRR % | L4: 3M % | M4: 6M % | N4: 1Y % (CAGR) | O4: 3Y % (CAGR) | P4: 5Y % (CAGR)
A5: HDFC Small Cap Fund - Direct Growth Plan | B5: HDFC Mutual Fund | C5: Equity | D5: Small Cap | E5: 15045815 | F5: 983601.71 | G5: 1292792.7 | H5: =G5-F5 -> 309190.95 | I5: =IF(F5=0,"-",H5/F5) -> 0.31434568 | J5: =G5/G$13 -> 0.10931762 | K5: =XIRR(Transactions!I5:I8,Transactions!D5:D8) -> 0.42874303 | L5: ='NAV History (Source Data)'!D5/'NAV History (Source Data)'!F5-1 -> 0.066935692 | M5: ='NAV History (Source Data)'!D5/'NAV History (Source Data)'!H5-1 -> 0.051319446 | N5: =('NAV History (Source Data)'!D5/'NAV History (Source Data)'!J5)^(365/365)-1 -> 0.012228448 | O5: =('NAV History (Source Data)'!D5/'NAV History (Source Data)'!L5)^(365/1095)-1 -> 0.13042022 | P5: =('NAV History (Source Data)'!D5/'NAV History (Source Data)'!N5)^(365/1825)-1 -> 0.15570768
A6: Kotak Midcap Fund- Direct Plan - Growth (Erstwhile Kotak Emerging Equity Scheme) | B6: Kotak Mutual Fund | C6: Equity | D6: Mid Cap | E6: 12734790 | F6: 1325000 | G6: 1591496.6 | H6: =G6-F6 -> 266496.63 | I6: =IF(F6=0,"-",H6/F6) -> 0.20112953 | J6: =G6/G$13 -> 0.13457581 | K6: =XIRR(Transactions!I9:I48,Transactions!D9:D48) -> 0.13788567 | L6: ='NAV History (Source Data)'!D6/'NAV History (Source Data)'!F6-1 -> 0.063288851 | M6: ='NAV History (Source Data)'!D6/'NAV History (Source Data)'!H6-1 -> 0.11112775 | N6: =('NAV History (Source Data)'!D6/'NAV History (Source Data)'!J6)^(365/365)-1 -> 0.09495368 | O6: =('NAV History (Source Data)'!D6/'NAV History (Source Data)'!L6)^(365/1095)-1 -> 0.2018011 | P6: =('NAV History (Source Data)'!D6/'NAV History (Source Data)'!N6)^(365/1825)-1 -> 0.17701286
A7: Parag Parikh Flexi Cap Fund - Direct Plan Growth (formerly Parag Parikh Long Term Value Fund) | B7: PPFAS Mutual Fund | C7: Equity | D7: Flexi Cap (incl. intl.) | E7: 17029743 | F7: 1000000 | G7: 1021047.9 | H7: =G7-F7 -> 21047.9 | I7: =IF(F7=0,"-",H7/F7) -> 0.0210479 | J7: =G7/G$13 -> 0.086339078 | K7: =XIRR(Transactions!I49:I54,Transactions!D49:D54) -> 0.017756172 | L7: ='NAV History (Source Data)'!D7/'NAV History (Source Data)'!F7-1 -> 0.0083524807 | M7: ='NAV History (Source Data)'!D7/'NAV History (Source Data)'!H7-1 -> -0.015702326 | N7: =('NAV History (Source Data)'!D7/'NAV History (Source Data)'!J7)^(365/365)-1 -> 0.0079108514 | O7: =('NAV History (Source Data)'!D7/'NAV History (Source Data)'!L7)^(365/1095)-1 -> 0.14787194 | P7: =('NAV History (Source Data)'!D7/'NAV History (Source Data)'!N7)^(365/1825)-1 -> 0.13717825
A8: Canara Robeco Large Cap Fund - Direct Growth | B8: Canara Robeco Mutual Fund | C8: Equity | D8: Large Cap | E8: 19959900451 | F8: 400000 | G8: 461915.1 | H8: =G8-F8 -> 61915.1 | I8: =IF(F8=0,"-",H8/F8) -> 0.15478775 | J8: =G8/G$13 -> 0.039059209 | K8: =XIRR(Transactions!I55:I57,Transactions!D55:D57) -> 0.071284934 | L8: ='NAV History (Source Data)'!D8/'NAV History (Source Data)'!F8-1 -> 0.040685217 | M8: ='NAV History (Source Data)'!D8/'NAV History (Source Data)'!H8-1 -> -0.0046422797 | N8: =('NAV History (Source Data)'!D8/'NAV History (Source Data)'!J8)^(365/365)-1 -> 0.014049234 | O8: =('NAV History (Source Data)'!D8/'NAV History (Source Data)'!L8)^(365/1095)-1 -> 0.11991928 | P8: =('NAV History (Source Data)'!D8/'NAV History (Source Data)'!N8)^(365/1825)-1 -> 0.11343171
A9: quant Multi Asset Allocation Fund - Direct Plan - Growth | B9: Quant MF | C9: Multi-Asset | D9: Equity+Debt+Gold | E9: 51065408774 | F9: 1000000 | G9: 1130434.8 | H9: =G9-F9 -> 130434.8 | I9: =IF(F9=0,"-",H9/F9) -> 0.1304348 | J9: =G9/G$13 -> 0.095588755 | K9: =XIRR(Transactions!I58:I63,Transactions!D58:D63) -> 0.16396496 | L9: ='NAV History (Source Data)'!D9/'NAV History (Source Data)'!F9-1 -> 0.043043573 | M9: ='NAV History (Source Data)'!D9/'NAV History (Source Data)'!H9-1 -> 0.04240692 | N9: =('NAV History (Source Data)'!D9/'NAV History (Source Data)'!J9)^(365/365)-1 -> 0.21282682 | O9: =('NAV History (Source Data)'!D9/'NAV History (Source Data)'!L9)^(365/1095)-1 -> 0.2302112 | P9: =('NAV History (Source Data)'!D9/'NAV History (Source Data)'!N9)^(365/1825)-1 -> 0.1958747
A10: NIPPON INDIA LARGE CAP FUND - DIRECT GROWTH PLAN GROWTH OPTION | B10: Nippon India Mutual Fund | C10: Equity | D10: Large Cap | E10: 499310094065 | F10: 2000000 | G10: 2123818.2 | H10: =G10-F10 -> 123818.21 | I10: =IF(F10=0,"-",H10/F10) -> 0.061909105 | J10: =G10/G$13 -> 0.17958854 | K10: =XIRR(Transactions!I64:I74,Transactions!D64:D74) -> 0.048150878 | L10: ='NAV History (Source Data)'!D10/'NAV History (Source Data)'!F10-1 -> 0.022733255 | M10: ='NAV History (Source Data)'!D10/'NAV History (Source Data)'!H10-1 -> -0.0041296806 | N10: =('NAV History (Source Data)'!D10/'NAV History (Source Data)'!J10)^(365/365)-1 -> 0.019036886 | O10: =('NAV History (Source Data)'!D10/'NAV History (Source Data)'!L10)^(365/1095)-1 -> 0.13349731 | P10: =('NAV History (Source Data)'!D10/'NAV History (Source Data)'!N10)^(365/1825)-1 -> 0.15804923
A11: NIPPON INDIA GROWTH MID CAP FUND - DIRECT GROWTH PLAN GROWTH OPTION | B11: Nippon India Mutual Fund | C11: Equity | D11: Mid Cap | E11: 499310094065 | F11: 2300000 | G11: 2602141.5 | H11: =G11-F11 -> 302141.47 | I11: =IF(F11=0,"-",H11/F11) -> 0.13136586 | J11: =G11/G$13 -> 0.22003522 | K11: =XIRR(Transactions!I75:I87,Transactions!D75:D87) -> 0.1241669 | L11: ='NAV History (Source Data)'!D11/'NAV History (Source Data)'!F11-1 -> 0.0505289 | M11: ='NAV History (Source Data)'!D11/'NAV History (Source Data)'!H11-1 -> 0.094508619 | N11: =('NAV History (Source Data)'!D11/'NAV History (Source Data)'!J11)^(365/365)-1 -> 0.12093187 | O11: =('NAV History (Source Data)'!D11/'NAV History (Source Data)'!L11)^(365/1095)-1 -> 0.2196476 | P11: =('NAV History (Source Data)'!D11/'NAV History (Source Data)'!N11)^(365/1825)-1 -> 0.19586385
A12: Axis Mid Cap Fund - Direct Growth | B12: Axis Mutual Fund | C12: Equity | D12: Mid Cap | E12: 910116656423 | F12: 945541.65 | G12: 1602376 | H12: =G12-F12 -> 656834.36 | I12: =IF(F12=0,"-",H12/F12) -> 0.69466465 | J12: =G12/G$13 -> 0.13549577 | K12: N/A | L12: ='NAV History (Source Data)'!D12/'NAV History (Source Data)'!F12-1 -> 0.059692581 | M12: ='NAV History (Source Data)'!D12/'NAV History (Source Data)'!H12-1 -> 0.10341077 | N12: =('NAV History (Source Data)'!D12/'NAV History (Source Data)'!J12)^(365/365)-1 -> 0.093470894 | O12: =('NAV History (Source Data)'!D12/'NAV History (Source Data)'!L12)^(365/1095)-1 -> 0.18076436 | P12: =('NAV History (Source Data)'!D12/'NAV History (Source Data)'!N12)^(365/1825)-1 -> 0.14571293
A13: TOTAL / PORTFOLIO | F13: =SUM(F5:F12) -> 9954143.4 | G13: =SUM(G5:G12) -> 11826023 | H13: =G13-F13 -> 1871879.4 | I13: =H13/F13 -> 0.18805028 | J13: =SUM(J5:J12) -> 1

Sheet Classification & Analysis
A1: Section 2 — Classification, Portfolio Health & Action Items
A2: Classifies each active holding by asset class, market-cap segment and AMC, then assesses concentration/overlap risk and lays out concrete next steps.
A4: ALLOCATION BY ASSET CLASS
A5: Asset Class | B5: Current Value (₹) | C5: Weight %
A6: Equity | B6: =SUMIFS('Holdings & Returns'!G:G,'Holdings & Returns'!C:C,A6) -> 10695588 | C6: =B6/'Holdings & Returns'!$G$13 -> 0.90441124
A7: Multi-Asset | B7: =SUMIFS('Holdings & Returns'!G:G,'Holdings & Returns'!C:C,A7) -> 1130434.8 | C7: =B7/'Holdings & Returns'!$G$13 -> 0.095588755
A9: ALLOCATION BY MARKET-CAP / STYLE SEGMENT
A10: Segment | B10: Current Value (₹) | C10: Weight %
A11: Large Cap | B11: =SUMIFS('Holdings & Returns'!G:G,'Holdings & Returns'!D:D,A11) -> 2585733.3 | C11: =B11/'Holdings & Returns'!$G$13 -> 0.21864775
A12: Mid Cap | B12: =SUMIFS('Holdings & Returns'!G:G,'Holdings & Returns'!D:D,A12) -> 5796014.1 | C12: =B12/'Holdings & Returns'!$G$13 -> 0.49010679
A13: Small Cap | B13: =SUMIFS('Holdings & Returns'!G:G,'Holdings & Returns'!D:D,A13) -> 1292792.7 | C13: =B13/'Holdings & Returns'!$G$13 -> 0.10931762
A14: Flexi Cap (incl. intl.) | B14: =SUMIFS('Holdings & Returns'!G:G,'Holdings & Returns'!D:D,A14) -> 1021047.9 | C14: =B14/'Holdings & Returns'!$G$13 -> 0.086339078
A15: Equity+Debt+Gold | B15: =SUMIFS('Holdings & Returns'!G:G,'Holdings & Returns'!D:D,A15) -> 1130434.8 | C15: =B15/'Holdings & Returns'!$G$13 -> 0.095588755
A17: ALLOCATION BY AMC (concentration check)
A18: AMC | B18: Current Value (₹) | C18: Weight %
A19: Nippon India Mutual Fund | B19: =SUMIFS('Holdings & Returns'!G:G,'Holdings & Returns'!B:B,A19) -> 4725959.7 | C19: =B19/'Holdings & Returns'!$G$13 -> 0.39962376
A20: Axis Mutual Fund | B20: =SUMIFS('Holdings & Returns'!G:G,'Holdings & Returns'!B:B,A20) -> 1602376 | C20: =B20/'Holdings & Returns'!$G$13 -> 0.13549577
A21: Kotak Mutual Fund | B21: =SUMIFS('Holdings & Returns'!G:G,'Holdings & Returns'!B:B,A21) -> 1591496.6 | C21: =B21/'Holdings & Returns'!$G$13 -> 0.13457581
A22: HDFC Mutual Fund | B22: =SUMIFS('Holdings & Returns'!G:G,'Holdings & Returns'!B:B,A22) -> 1292792.7 | C22: =B22/'Holdings & Returns'!$G$13 -> 0.10931762
A23: Quant MF | B23: =SUMIFS('Holdings & Returns'!G:G,'Holdings & Returns'!B:B,A23) -> 1130434.8 | C23: =B23/'Holdings & Returns'!$G$13 -> 0.095588755
A24: PPFAS Mutual Fund | B24: =SUMIFS('Holdings & Returns'!G:G,'Holdings & Returns'!B:B,A24) -> 1021047.9 | C24: =B24/'Holdings & Returns'!$G$13 -> 0.086339078
A25: Canara Robeco Mutual Fund | B25: =SUMIFS('Holdings & Returns'!G:G,'Holdings & Returns'!B:B,A25) -> 461915.1 | C25: =B25/'Holdings & Returns'!$G$13 -> 0.039059209
A30: HOW GOOD IS THIS PORTFOLIO — STRENGTHS
A31: + Solidly profitable overall: +Rs.18.8 lakh gain on Rs.99.5 lakh invested (+18.8% absolute) over a 3-year build-up, with every active holding in the green.
A32: + 100% Direct plans across all current holdings — no trail-commission drag from Regular plans (the one Regular-plan legacy folio, HDFC Value Fund, was fully exited).
A33: + Genuine SIP discipline: Kotak Midcap Fund has run 37 monthly instalments since Aug-2023 — the single best-behaved habit in the portfolio.
A34: + Spread across 7 AMCs and 5 style segments — the raw ingredients for diversification are present, even if the mix needs rebalancing (see below).
A35: + Individual fund-level XIRRs (where verifiable) are healthy and broadly ahead of typical FD/debt returns: quant Multi Asset Allocation 16.4%, Kotak Midcap 13.8%, Nippon Growth Mid Cap 12.4%.
A37: WHAT'S NOT GOOD — CONCENTRATION, GAPS & RISK
A38: ! Mid-cap heavy: 49% of the book sits in THREE separate mid-cap funds (Kotak Midcap, Axis Mid Cap, Nippon Growth Mid Cap). That's not diversification — it's one large, volatile bet split three ways, almost certainly with overlapping stock holdings.
A39: ! Single-AMC concentration: Nippon India alone accounts for 40% of the portfolio (Large Cap + Growth Mid Cap funds combined) — a lot resting on one fund house's process and fund managers.
A40: ! Zero dedicated debt/fixed-income fund: the only non-pure-equity sleeve is the quant Multi Asset Allocation fund (9.6% of the book), which itself is mostly equity. On a ~Rs.1.18 crore mutual-fund book this leaves no ballast for a market drawdown and no 'dry powder' to rebalance into a dip.
A41: ! Large cap is under-weighted at 21.9% against a 49% mid-cap tilt — an aggressive skew that should be a deliberate choice, not a side-effect of scattered fund selection.
A42: ! Two folios have incomplete transaction history in the source CAS: Axis Mid Cap (Rs.16.02 lakh current value, 13.5% of the portfolio) has NO transaction records at all, and HDFC Small Cap is missing ~39% of its invested capital's transaction trail. XIRR for both is either unavailable or only indicative — and this same gap would show up if this data were ever needed for capital-gains tax reporting.
... A53: 7. Revisit why Kotak Multicap was exited at a loss and why quant Multi Cap was redeemed in two tranches — capture the lesson before the next fund-selection decision.

Sheet Transactions
A1: Transaction Log (cleaned — admin/zero-amount entries removed)
A2: Each active fund's block ends with a 'Valuation' row (current value as of 01-Aug-2026) so =XIRR() can be computed directly over the range below. Source: cas_detailed_report_2026_08_01_124122.xlsx, Transaction Details tab.
A4: Scheme | B4: AMC | C4: Segment | D4: Date | E4: Description | F4: NAV (₹) | G4: Units | H4: Amount (₹) | I4: Cashflow for XIRR (₹)
A5: HDFC Small Cap Fund - Direct Growth Plan | B5: HDFC Mutual Fund | C5: Small Cap | D5: 45287 | E5: Purchase - via HDFCMFOnline | F5: 128.43 | G5: 1557.191 | H5: 199990 | I5: =-H5 -> -199990
A6: HDFC Small Cap Fund - Direct Growth Plan | B6: HDFC Mutual Fund | C6: Small Cap | D6: 45414 | E6: Purchase - via HDFCMFOnline | F6: 141.356 | G6: 1414.797 | H6: 199990 | I6: =-H6 -> -199990
A7: HDFC Small Cap Fund - Direct Growth Plan | B7: HDFC Mutual Fund | C7: Small Cap | D7: 45688 | E7: Purchase - via HDFCMFMobile | F7: 144.041 | G7: 1388.424 | H7: 199990 | I7: =-H7 -> -199990
A8: HDFC Small Cap Fund - Direct Growth Plan | B8: HDFC Mutual Fund | C8: Small Cap | D8: 46235 | E8: Valuation as of statement date (current holding value) | I8: 1292792.7
A9: Kotak Midcap Fund- Direct Plan - Growth (Erstwhile Kotak Emerging Equity Scheme) | B9: Kotak Mutual Fund | C9: Mid Cap | D9: 45139 | E9: Systematic Purchase (Continuous Offer) - Instalment 1/240 - via Internet | F9: 99.363 | G9: 251.59 | H9: 24998.75 | I9: =-H9 -> -24998.75
A10: Kotak Midcap Fund- Direct Plan - Growth (Erstwhile Kotak Emerging Equity Scheme) | B10: Kotak Mutual Fund | C10: Mid Cap | D10: 45168 | E10: Systematic Purchase (Continuous Offer) - Instalment 2/240 - via Internet | F10: 102.458 | G10: 243.99 | H10: 24998.75 | I10: =-H10 -> -24998.75
A11: Kotak Midcap Fund- Direct Plan - Growth (Erstwhile Kotak Emerging Equity Scheme) | B11: Kotak Mutual Fund | C11: Mid Cap | D11: 45202 | E11: Systematic Purchase (Continuous Offer) - Instalment 3/240 - via Internet | F11: 104.114 | G11: 240.109 | H11: 24998.75 | I11: =-H11 -> -24998.75
A12: Kotak Midcap Fund- Direct Plan - Growth (Erstwhile Kotak Emerging Equity Scheme) | B12: Kotak Mutual Fund | C12: Mid Cap | D12: 45230 | E12: Systematic Purchase (Continuous Offer) - Instalment 4/240 - via Internet | F12: 101.902 | G12: 245.321 | H12: 24998.75 | I12: =-H12 -> -24998.75
A13: Kotak Midcap Fund- Direct Plan - Growth (Erstwhile Kotak Emerging Equity Scheme) | B13: Kotak Mutual Fund | C13: Mid Cap | D13: 45260 | E13: Systematic Purchase (Continuous Offer) - Instalment 5/240 - via Internet | F13: 109.04 | G13: 229.262 | H13: 24998.75 | I13: =-H13 -> -24998.75
A14: Kotak Midcap Fund- Direct Plan - Growth (Erstwhile Kotak Emerging Equity Scheme) | B14: Kotak Mutual Fund | C14: Mid Cap | D14: 45292 | E14: Systematic Purchase (Continuous Offer) - Instalment 6/240 - via Internet | F14: 114.351 | G14: 218.614 | H14: 24998.75 | I14: =-H14 -> -24998.75
A15: Kotak Midcap Fund- Direct Plan - Growth (Erstwhile Kotak Emerging Equity Scheme) | B15: Kotak Mutual Fund | C15: Mid Cap | D15: 45321 | E15: Systematic Purchase (Continuous Offer) - Instalment 7/240 - via Internet | F15: 113.553 | G15: 220.151 | H15: 24998.75 | I15: =-H15 -> -24998.75
A16: Kotak Midcap Fund- Direct Plan - Growth (Erstwhile Kotak Emerging Equity Scheme) | B16: Kotak Mutual Fund | C16: Mid Cap | D16: 45352 | E16: Systematic Purchase (Continuous Offer) - Instalment 8/240 - via Internet | F16: 117.856 | G16: 212.113 | H16: 24998.75 | I16: =-H16 -> -24998.75
A17: Kotak Midcap Fund- Direct Plan - Growth (Erstwhile Kotak Emerging Equity Scheme) | B17: Kotak Mutual Fund | C17: Mid Cap | D17: 45384 | E17: Systematic Purchase (Continuous Offer) - Instalment 9/240 - via Internet | F17: 120.234 | G17: 207.917 | H17: 24998.75 | I17: =-H17 -> -24998.75
A18: Kotak Midcap Fund- Direct Plan - Growth (Erstwhile Kotak Emerging Equity Scheme) | B18: Kotak Mutual Fund | C18: Mid Cap | D18: 45412 | E18: Systematic Purchase (Continuous Offer) - Instalment 10/240 - via Internet | F18: 125.74 | G18: 198.813 | H18: 24998.75 | I18: =-H18 -> -24998.75
A19: Kotak Midcap Fund- Direct Plan - Growth (Erstwhile Kotak Emerging Equity Scheme) | B19: Kotak Mutual Fund | C19: Mid Cap | D19: 45442 | E19: Systematic Purchase (Continuous Offer) - Instalment 11/240 - via Internet | F19: 132.652 | G19: 188.454 | H19: 24998.75 | I19: =-H19 -> -24998.75
A20: Kotak Midcap Fund- Direct Plan - Growth (Erstwhile Kotak Emerging Equity Scheme) | B20: Kotak Mutual Fund | C20: Mid Cap | D20: 45474 | E20: Systematic Purchase (Continuous Offer) - Instalment 12/240 - via Internet | F20: 146.633 | G20: 170.485 | H20: 24998.75 | I20: =-H20 -> -24998.75
... A47: Kotak Midcap Fund- Direct Plan - Growth (Erstwhile Kotak Emerging Equity Scheme) | B47: Kotak Mutual Fund | C47: Mid Cap | D47: 46233 | E47: Systematic Purchase (Continuous Offer) - Instalment 37/240 - via Internet | F47: 170.104 | G47: 146.962 | H47: 24998.75 | I47: =-H47 -> -24998.75
A48: Kotak Midcap Fund- Direct Plan - Growth (Erstwhile Kotak Emerging Equity Scheme) | B48: Kotak Mutual Fund | C48: Mid Cap | D48: 46235 | E48: Valuation as of statement date (current holding value) | I48: 1591496.6
A49: Parag Parikh Flexi Cap Fund - Direct Plan Growth (formerly Parag Parikh Long Term Value Fund) | B49: PPFAS Mutual Fund | C49: Flexi Cap (incl. intl.) | D49: 45789 | E49: Purchase- via MFCentral | F49: 89.5367 | G49: 2233.609 | H49: 199990 | I49: =-H49 -> -199990
A50: Parag Parikh Flexi Cap Fund - Direct Plan Growth (formerly Parag Parikh Long Term Value Fund) | B50: PPFAS Mutual Fund | C50: Flexi Cap (incl. intl.) | D50: 45798 | E50: Purchase- via MFCentral | F50: 89.8657 | G50: 2225.432 | H50: 199990 | I50: =-H50 -> -199990
A51: Parag Parikh Flexi Cap Fund - Direct Plan Growth (formerly Parag Parikh Long Term Value Fund) | B51: PPFAS Mutual Fund | C51: Flexi Cap (incl. intl.) | D51: 45799 | E51: Purchase- via MFCentral | F51: 89.4835 | G51: 2234.937 | H51: 199990 | I51: =-H51 -> -199990
A52: Parag Parikh Flexi Cap Fund - Direct Plan Growth (formerly Parag Parikh Long Term Value Fund) | B52: PPFAS Mutual Fund | C52: Flexi Cap (incl. intl.) | D52: 45806 | E52: Purchase- via MFCentral | F52: 89.9176 | G52: 2224.147 | H52: 199990 | I52: =-H52 -> -199990
A53: Parag Parikh Flexi Cap Fund - Direct Plan Growth (formerly Parag Parikh Long Term Value Fund) | B53: PPFAS Mutual Fund | C53: Flexi Cap (incl. intl.) | D53: 45818 | E53: Purchase- via MFCentral | F53: 91.9973 | G53: 2173.868 | H53: 199990 | I53: =-H53 -> -199990
A54: Parag Parikh Flexi Cap Fund - Direct Plan Growth (formerly Parag Parikh Long Term Value Fund) | B54: PPFAS Mutual Fund | C54: Flexi Cap (incl. intl.) | D54: 46235 | E54: Valuation as of statement date (current holding value) | I54: 1021047.9
A55: Canara Robeco Large Cap Fund - Direct Growth | B55: Canara Robeco Mutual Fund | C55: Large Cap | D55: 45293 | E55: Purchase Trxn.Ref.No.240029488533HDFC Bank Ltd | F55: 57.94 | G55: 3451.674 | H55: 199990 | I55: =-H55 -> -199990
A56: Canara Robeco Large Cap Fund - Direct Growth | B56: Canara Robeco Mutual Fund | C56: Large Cap | D56: 45657 | E56: Purchase Trxn.Ref.No.243668145815HDFC Bank Ltd | F56: 69.33 | G56: 2884.61 | H56: 199990 | I56: =-H56 -> -199990
A57: Canara Robeco Large Cap Fund - Direct Growth | B57: Canara Robeco Mutual Fund | C57: Large Cap | D57: 46235 | E57: Valuation as of statement date (current holding value) | I57: 461915.1
A58: quant Multi Asset Allocation Fund - Direct Plan - Growth | B58: Quant MF | C58: Equity+Debt+Gold | D58: 45394 | E58: New Purchase Trxn.Ref.No.241033038154HDFC Bank Ltd | F58: 135.561 | G58: 1475.277 | H58: 199990 | I58: =-H58 -> -199990
A59: quant Multi Asset Allocation Fund - Direct Plan - Growth | B59: Quant MF | C59: Equity+Debt+Gold | D59: 46022 | E59: Additional Purchase Trxn.Ref.No.253658230131HDFC Bank Ltd | F59: 170.2774 | G59: 1174.495 | H59: 199990 | I59: =-H59 -> -199990
A60: quant Multi Asset Allocation Fund - Direct Plan - Growth | B60: Quant MF | C60: Equity+Debt+Gold | D60: 46113 | E60: Additional Purchase Trxn.Ref.No.2693709100141HDFC Bank Ltd | F60: 166.0331 | G60: 1204.519 | H60: 199990 | I60: =-H60 -> -199990
A61: quant Multi Asset Allocation Fund - Direct Plan - Growth | B61: Quant MF | C61: Equity+Debt+Gold | D61: 46113 | E61: Additional Purchase Trxn.Ref.No.2693709100144HDFC Bank Ltd | F61: 166.0331 | G61: 1204.519 | H61: 199990 | I61: =-H61 -> -199990
A62: quant Multi Asset Allocation Fund - Direct Plan - Growth | B62: Quant MF | C62: Equity+Debt+Gold | D62: 46148 | E62: Additional Purchase Trxn.Ref.No.2693712600070HDFC Bank Ltd | F62: 178.3029 | G62: 1121.631 | H62: 199990 | I62: =-H62 -> -199990
A63: quant Multi Asset Allocation Fund - Direct Plan - Growth | B63: Quant MF | C63: Equity+Debt+Gold | D63: 46235 | E63: Valuation as of statement date (current holding value) | I63: 1130434.8
A64: NIPPON INDIA LARGE CAP FUND - DIRECT GROWTH PLAN GROWTH OPTION | B64: Nippon India Mutual Fund | C64: Large Cap | D64: 45293 | E64: Purchase Trxn.Ref.No.240029494692HDFC Bank Ltd | F64: 80.3585 | G64: 2488.722 | H64: 199990 | I64: =-H64 -> -199990
A65: NIPPON INDIA LARGE CAP FUND - DIRECT GROWTH PLAN GROWTH OPTION | B65: Nippon India Mutual Fund | C65: Large Cap | D65: 45681 | E65: Purchase Trxn.Ref.No.250247750155HDFC Bank Ltd | F65: 91.4588 | G65: 2186.668 | H65: 199990 | I65: =-H65 -> -199990
A66: NIPPON INDIA LARGE CAP FUND - DIRECT GROWTH PLAN GROWTH OPTION | B66: Nippon India Mutual Fund | C66: Large Cap | D66: 45720 | E66: Purchase Trxn.Ref.No.250632162408HDFC Bank Ltd | F66: 87.1643 | G66: 2294.403 | H66: 199990 | I66: =-H66 -> -199990
A67: NIPPON INDIA LARGE CAP FUND - DIRECT GROWTH PLAN GROWTH OPTION | B67: Nippon India Mutual Fund | C67: Large Cap | D67: 45789 | E67: Purchase Trxn.Ref.No.251327518246HDFC Bank Ltd | F67: 97.9099 | G67: 2042.592 | H67: 199990 | I67: =-H67 -> -199990
...

Sheet NAV History (Source Data)
A1: NAV Reference Points Behind the Trailing Returns
A2: Source: mfapi.in (AMFI-mandated daily NAV history), fetched 01-Aug-2026. Current NAV/unit = CAS current value ÷ units (as of 01-Aug-2026), not mfapi's latest print (which lagged by several weeks at fetch time).
A4: Scheme | B4: Current Value (₹) | C4: Units | D4: Current NAV/unit | E4: 3M-ago date | F4: 3M-ago NAV | G4: 6M-ago date | H4: 6M-ago NAV | I4: 1Y-ago date | J4: 1Y-ago NAV | K4: 3Y-ago date | L4: 3Y-ago NAV | M4: 5Y-ago date | N4: 5Y-ago NAV
A5: HDFC Small Cap Fund - Direct Growth Plan | B5: 1292792.7 | C5: 8042.156 | D5: =B5/C5 -> 160.752 | E5: 46142 | F5: 150.667 | G5: 46052 | H5: 152.905 | I5: 45870 | J5: 158.81 | K5: 45140 | L5: 111.285 | M5: 44410 | N5: 77.968
A6: Kotak Midcap Fund- Direct Plan - Growth (Erstwhile Kotak Emerging Equity Scheme) | B6: 1591496.6 | C6: 9324.611 | D6: =B6/C6 -> 170.677 | E6: 46142 | F6: 160.518 | G6: 46052 | H6: 153.607 | I6: 45870 | J6: 155.876 | K6: 45140 | L6: 98.328 | M6: 44410 | N6: 75.556
A7: Parag Parikh Flexi Cap Fund - Direct Plan Growth (formerly Parag Parikh Long Term Value Fund) | B7: 1021047.9 | C7: 11091.993 | D7: =B7/C7 -> 92.0527 | E7: 46142 | F7: 91.2902 | G7: 46052 | H7: 93.5212 | I7: 45870 | J7: 91.3302 | K7: 45140 | L7: 60.8634 | M7: 44410 | N7: 48.4054
A8: Canara Robeco Large Cap Fund - Direct Growth | B8: 461915.1 | C8: 6336.284 | D8: =B8/C8 -> 72.899999 | E8: 46142 | F8: 70.05 | G8: 46052 | H8: 73.24 | I8: 45870 | J8: 71.89 | K8: 45140 | L8: 51.9 | M8: 44410 | N8: 42.6
A9: quant Multi Asset Allocation Fund - Direct Plan - Growth | B9: 1130434.8 | C9: 6180.441 | D9: =B9/C9 -> 182.9052 | E9: 46142 | F9: 175.3572 | G9: 46052 | H9: 175.4643 | I9: 45870 | J9: 150.809 | K9: 45140 | L9: 98.2397 | M9: 44410 | N9: 74.7821
A10: NIPPON INDIA LARGE CAP FUND - DIRECT GROWTH PLAN GROWTH OPTION | B10: 2123818.2 | C10: 20859.929 | D10: =B10/C10 -> 101.8133 | E10: 46142 | F10: 99.5502 | G10: 46052 | H10: 102.2355 | I10: 45870 | J10: 99.9113 | K10: 45140 | L10: 69.9106 | M10: 44410 | N10: 48.8843
A11: NIPPON INDIA GROWTH MID CAP FUND - DIRECT GROWTH PLAN GROWTH OPTION | B11: 2602141.5 | C11: 521.776 | D11: =B11/C11 -> 4987.0854 | E11: 46142 | F11: 4747.2139 | G11: 46052 | H11: 4556.4606 | I11: 45870 | J11: 4449.0531 | K11: 45140 | L11: 2748.8036 | M11: 44410 | N11: 2039.0981
A12: Axis Mid Cap Fund - Direct Growth | B12: 1602376 | C12: 11282.749 | D12: =B12/C12 -> 142.02 | E12: 46142 | F12: 134.02 | G12: 46053 | H12: 128.71 | I12: 45870 | J12: 129.88 | K12: 45140 | L12: 86.27 | M12: 44410 | N12: 71.94

Sheet Exited Positions
A1: Fully Redeemed Folios (realized gain/loss)
A2: These three folios were fully exited during the statement period. Invested/Redeemed pull via SUMIFS from the Transactions tab.
A4: Scheme | B4: AMC | C4: Segment | D4: Plan | E4: Total Invested (₹) | F4: Total Redeemed (₹) | G4: Realized Gain/Loss (₹) | H4: Holding Period
A5: HDFC Value Fund - Regular Plan - Growth (formerly HDFC Capital Builder Fund) | B5: HDFC Mutual Fund | C5: Large & Mid Cap (Value) | D5: Regular | E5: =SUMIFS(Transactions!H:H,Transactions!A:A,A5,Transactions!H:H,">0") -> 0 | F5: =SUMIFS(Transactions!H:H,Transactions!A:A,A5,Transactions!H:H,"<0")*-1 -> 7073.27 | G5: =F5-E5 -> 7073.27 | H5: 2025-05-06 to 2025-05-06
A6: Kotak Multicap Fund Direct Plan - Growth | B6: Kotak Mutual Fund | C6: Multi Cap | D6: Direct | E6: =SUMIFS(Transactions!H:H,Transactions!A:A,A6,Transactions!H:H,">0") -> 399980 | F6: =SUMIFS(Transactions!H:H,Transactions!A:A,A6,Transactions!H:H,"<0")*-1 -> 360132.31 | G6: =F6-E6 -> -39847.69 | H6: 2024-12-16 to 2025-05-06
A7: quant Multi Cap Fund - Direct Plan - Growth | B7: Quant MF | C7: Multi Cap | D7: Direct | E7: =SUMIFS(Transactions!H:H,Transactions!A:A,A7,Transactions!H:H,">0") -> 1199940 | F7: =SUMIFS(Transactions!H:H,Transactions!A:A,A7,Transactions!H:H,"<0")*-1 -> 1223221.8 | G7: =F7-E7 -> 23281.81 | H7: 2023-09-05 to 2026-02-06
A8: TOTAL | E8: =SUM(E5:E7) -> 1599920 | F8: =SUM(F5:F7) -> 1590427.4 | G8: =F8-E8 -> -9492.61

Sheet Data Quality Notes
A1: Data Quality Notes & Methodology
A3: GAPS FOUND IN THE SOURCE CAS
A4: - Axis Mid Cap Fund - Direct Growth (Folio 910116656423): the Portfolio Details tab shows Rs.9,45,542 invested / Rs.16,02,376 current value, but the Transaction Details tab has ZERO rows for this folio. Cause unknown (possibly a switch-in, transfer, or a CAS export limited to one RTA). XIRR cannot be computed; only the CAS's own invested/current figures are used, giving a simple absolute return of +69.5% since an unknown start date.
A5: - HDFC Small Cap Fund - Direct Growth Plan (Folio 15045815): only Rs.5,99,970 of the Rs.9,83,602 invested value (about 61%) is backed by transaction rows in the source file. The XIRR shown (Holdings & Returns tab) uses only the available transactions plus the full current value, so it is directionally right but likely OVERSTATED — flagged with a comment on that cell.
A6: - quant Multi Asset Allocation Fund - Direct Plan - Growth: the CAS Category column labels this fund 'DEBT'. It is actually a multi-asset hybrid (equity + debt + gold/commodities). This workbook reclassifies it as 'Multi-Asset' throughout — the CAS's own category field should not be trusted for this scheme.
A7: - mfapi.in's latest available NAV for these schemes at fetch time (01-Aug-2026) lagged the statement date by 3-8 weeks. To keep 'now' consistent with the CAS, every trailing-return calculation anchors the current side on the CAS's current value / units, not on mfapi's most recent NAV print — only the historical (3M/6M/1Y/3Y/5Y-ago) NAV points come from mfapi.
A9: METHODOLOGY
A10: - XIRR (Holdings & Returns, Summary): native Excel =XIRR() over each fund's actual purchase/redemption cash flows (Transactions tab) plus one final 'valuation' cash flow equal to current holding value on 01-Aug-2026. Purchases are negative cash flows, redemptions/valuation are positive.
A11: - Portfolio XIRR (Summary tab): computed the same way over the combined cash-flow log of the 7 funds that have complete or partial transaction records — Axis Mid Cap is excluded because including its current value with no matching outflow would fabricate a return. This means the portfolio XIRR covers ~90.5% of total invested capital (Rs.90.09 lakh of Rs.99.54 lakh).
A12: - 3M / 6M returns: simple point-to-point NAV change, (current NAV / NAV N days ago) - 1. Not annualised, matching standard fund-factsheet convention.
A13: - 1Y / 3Y / 5Y returns: annualised (CAGR), (current NAV / NAV N years ago) ^ (365/days) - 1.
A14: - 'Total Return %' column (Holdings & Returns): simple (Current Value - Invested Value) / Invested Value from the CAS figures directly — reliable regardless of any transaction-history gaps, since it only needs the two endpoint values.
... A18: Download a combined CAMS + KFinTech CAS covering 'since inception' from mfcentral.com (Consolidated Account Statement, all-mutual-fund option) and re-run this workbook's data-prep step — that should close the Axis Mid Cap and HDFC Small Cap gaps and make every XIRR figure fully reliable.
